[2019-01-12 12:06:37,165] {/Users/iman/Python/rest_training/lib/python3.7/site-packages/flask/app.py:1761} ERROR - Exception on /name [GET]
Traceback (most recent call last):
  File "/Users/iman/Python/rest_training/lib/python3.7/site-packages/flask/app.py", line 1813, in full_dispatch_request
    rv = self.dispatch_request()
  File "/Users/iman/Python/rest_training/lib/python3.7/site-packages/flask/app.py", line 1799, in dispatch_request
    return self.view_functions[rule.endpoint](**req.view_args)
  File "/Users/iman/Python/rest_training/lib/python3.7/site-packages/flask_restful/__init__.py", line 458, in wrapper
    resp = resource(*args, **kwargs)
  File "/Users/iman/Python/rest_training/lib/python3.7/site-packages/flask/views.py", line 88, in view
    return self.dispatch_request(*args, **kwargs)
  File "/Users/iman/Python/rest_training/lib/python3.7/site-packages/flask_restful/__init__.py", line 573, in dispatch_request
    resp = meth(*args, **kwargs)
  File "part-1.3-log_and_error/app.py", line 57, in get
    raise Exception('This is 500')
Exception: This is 500
[2019-01-12 12:06:37,167] {part-1.3-log_and_error/app.py:32} WARNING - ERROR_LOG	400 Bad Request: The browser (or proxy) sent a request that this server could not understand.
[2019-01-13 08:50:29,350] {/Users/iman/Python/rest_training/lib/python3.7/site-packages/flask/app.py:1761} ERROR - Exception on /name [GET]
Traceback (most recent call last):
  File "/Users/iman/Python/rest_training/lib/python3.7/site-packages/flask/app.py", line 1813, in full_dispatch_request
    rv = self.dispatch_request()
  File "/Users/iman/Python/rest_training/lib/python3.7/site-packages/flask/app.py", line 1799, in dispatch_request
    return self.view_functions[rule.endpoint](**req.view_args)
  File "/Users/iman/Python/rest_training/lib/python3.7/site-packages/flask_restful/__init__.py", line 458, in wrapper
    resp = resource(*args, **kwargs)
  File "/Users/iman/Python/rest_training/lib/python3.7/site-packages/flask/views.py", line 88, in view
    return self.dispatch_request(*args, **kwargs)
  File "/Users/iman/Python/rest_training/lib/python3.7/site-packages/flask_restful/__init__.py", line 573, in dispatch_request
    resp = meth(*args, **kwargs)
  File "part-1.3-log_and_error/app.py", line 54, in get
    raise Exception('Test internal server error')
Exception: Test internal server error
[2019-01-13 08:51:24,731] {/Users/iman/Python/rest_training/lib/python3.7/site-packages/flask/app.py:1761} ERROR - Exception on /name [GET]
Traceback (most recent call last):
  File "/Users/iman/Python/rest_training/lib/python3.7/site-packages/flask/app.py", line 1813, in full_dispatch_request
    rv = self.dispatch_request()
  File "/Users/iman/Python/rest_training/lib/python3.7/site-packages/flask/app.py", line 1799, in dispatch_request
    return self.view_functions[rule.endpoint](**req.view_args)
  File "/Users/iman/Python/rest_training/lib/python3.7/site-packages/flask_restful/__init__.py", line 458, in wrapper
    resp = resource(*args, **kwargs)
  File "/Users/iman/Python/rest_training/lib/python3.7/site-packages/flask/views.py", line 88, in view
    return self.dispatch_request(*args, **kwargs)
  File "/Users/iman/Python/rest_training/lib/python3.7/site-packages/flask_restful/__init__.py", line 573, in dispatch_request
    resp = meth(*args, **kwargs)
  File "part-1.3-log_and_error/app.py", line 54, in get
    raise Exception('Test internal server error')
Exception: Test internal server error
[2019-01-13 08:51:31,111] {/Users/iman/Python/rest_training/lib/python3.7/site-packages/flask/app.py:1761} ERROR - Exception on /name [GET]
Traceback (most recent call last):
  File "/Users/iman/Python/rest_training/lib/python3.7/site-packages/flask/app.py", line 1813, in full_dispatch_request
    rv = self.dispatch_request()
  File "/Users/iman/Python/rest_training/lib/python3.7/site-packages/flask/app.py", line 1799, in dispatch_request
    return self.view_functions[rule.endpoint](**req.view_args)
  File "/Users/iman/Python/rest_training/lib/python3.7/site-packages/flask_restful/__init__.py", line 458, in wrapper
    resp = resource(*args, **kwargs)
  File "/Users/iman/Python/rest_training/lib/python3.7/site-packages/flask/views.py", line 88, in view
    return self.dispatch_request(*args, **kwargs)
  File "/Users/iman/Python/rest_training/lib/python3.7/site-packages/flask_restful/__init__.py", line 573, in dispatch_request
    resp = meth(*args, **kwargs)
  File "part-1.3-log_and_error/app.py", line 54, in get
    raise Exception('Test internal server error')
Exception: Test internal server error
[2019-01-13 08:51:54,022] {/Users/iman/Python/rest_training/lib/python3.7/site-packages/flask/app.py:1761} ERROR - Exception on /name [GET]
Traceback (most recent call last):
  File "/Users/iman/Python/rest_training/lib/python3.7/site-packages/flask/app.py", line 1813, in full_dispatch_request
    rv = self.dispatch_request()
  File "/Users/iman/Python/rest_training/lib/python3.7/site-packages/flask/app.py", line 1799, in dispatch_request
    return self.view_functions[rule.endpoint](**req.view_args)
  File "/Users/iman/Python/rest_training/lib/python3.7/site-packages/flask_restful/__init__.py", line 458, in wrapper
    resp = resource(*args, **kwargs)
  File "/Users/iman/Python/rest_training/lib/python3.7/site-packages/flask/views.py", line 88, in view
    return self.dispatch_request(*args, **kwargs)
  File "/Users/iman/Python/rest_training/lib/python3.7/site-packages/flask_restful/__init__.py", line 573, in dispatch_request
    resp = meth(*args, **kwargs)
  File "part-1.3-log_and_error/app.py", line 54, in get
    raise Exception('Test internal server error')
Exception: Test internal server error
[2019-01-13 08:52:12,687] {/Users/iman/Python/rest_training/lib/python3.7/site-packages/flask/app.py:1761} ERROR - Exception on /name [GET]
Traceback (most recent call last):
  File "/Users/iman/Python/rest_training/lib/python3.7/site-packages/flask/app.py", line 1813, in full_dispatch_request
    rv = self.dispatch_request()
  File "/Users/iman/Python/rest_training/lib/python3.7/site-packages/flask/app.py", line 1799, in dispatch_request
    return self.view_functions[rule.endpoint](**req.view_args)
  File "/Users/iman/Python/rest_training/lib/python3.7/site-packages/flask_restful/__init__.py", line 458, in wrapper
    resp = resource(*args, **kwargs)
  File "/Users/iman/Python/rest_training/lib/python3.7/site-packages/flask/views.py", line 88, in view
    return self.dispatch_request(*args, **kwargs)
  File "/Users/iman/Python/rest_training/lib/python3.7/site-packages/flask_restful/__init__.py", line 573, in dispatch_request
    resp = meth(*args, **kwargs)
  File "part-1.3-log_and_error/app.py", line 54, in get
    raise Exception('Test internal server error')
Exception: Test internal server error
[2019-01-13 08:52:21,019] {part-1.3-log_and_error/app.py:27} WARNING - REQUEST_LOG	{"request": {"name": "iman", "age": 30, "sex": "male"}, "response": {"name": "iman", "age": 30, "sex": "male"}}
[2019-01-13 08:52:23,761] {/Users/iman/Python/rest_training/lib/python3.7/site-packages/flask/app.py:1761} ERROR - Exception on /name [GET]
Traceback (most recent call last):
  File "/Users/iman/Python/rest_training/lib/python3.7/site-packages/flask/app.py", line 1813, in full_dispatch_request
    rv = self.dispatch_request()
  File "/Users/iman/Python/rest_training/lib/python3.7/site-packages/flask/app.py", line 1799, in dispatch_request
    return self.view_functions[rule.endpoint](**req.view_args)
  File "/Users/iman/Python/rest_training/lib/python3.7/site-packages/flask_restful/__init__.py", line 458, in wrapper
    resp = resource(*args, **kwargs)
  File "/Users/iman/Python/rest_training/lib/python3.7/site-packages/flask/views.py", line 88, in view
    return self.dispatch_request(*args, **kwargs)
  File "/Users/iman/Python/rest_training/lib/python3.7/site-packages/flask_restful/__init__.py", line 573, in dispatch_request
    resp = meth(*args, **kwargs)
  File "part-1.3-log_and_error/app.py", line 54, in get
    raise Exception('Test internal server error')
Exception: Test internal server error
[2019-01-13 08:52:35,195] {/Users/iman/Python/rest_training/lib/python3.7/site-packages/flask/app.py:1761} ERROR - Exception on /name [GET]
Traceback (most recent call last):
  File "/Users/iman/Python/rest_training/lib/python3.7/site-packages/flask/app.py", line 1813, in full_dispatch_request
    rv = self.dispatch_request()
  File "/Users/iman/Python/rest_training/lib/python3.7/site-packages/flask/app.py", line 1799, in dispatch_request
    return self.view_functions[rule.endpoint](**req.view_args)
  File "/Users/iman/Python/rest_training/lib/python3.7/site-packages/flask_restful/__init__.py", line 458, in wrapper
    resp = resource(*args, **kwargs)
  File "/Users/iman/Python/rest_training/lib/python3.7/site-packages/flask/views.py", line 88, in view
    return self.dispatch_request(*args, **kwargs)
  File "/Users/iman/Python/rest_training/lib/python3.7/site-packages/flask_restful/__init__.py", line 573, in dispatch_request
    resp = meth(*args, **kwargs)
  File "part-1.3-log_and_error/app.py", line 54, in get
    raise Exception('Test internal server error')
Exception: Test internal server error
[2019-01-13 08:52:35,201] {part-1.3-log_and_error/app.py:27} WARNING - REQUEST_LOG	{"request": null, "response": {"message": "Internal Server Error"}}
