[2019-01-13 08:52:58,905] {/Users/iman/Python/rest_training/lib/python3.7/site-packages/flask/app.py:1761} ERROR - Exception on /name [GET]
Traceback (most recent call last):
  File "/Users/iman/Python/rest_training/lib/python3.7/site-packages/flask/app.py", line 1813, in full_dispatch_request
    rv = self.dispatch_request()
  File "/Users/iman/Python/rest_training/lib/python3.7/site-packages/flask/app.py", line 1799, in dispatch_request
    return self.view_functions[rule.endpoint](**req.view_args)
  File "/Users/iman/Python/rest_training/lib/python3.7/site-packages/flask_restful/__init__.py", line 458, in wrapper
    resp = resource(*args, **kwargs)
  File "/Users/iman/Python/rest_training/lib/python3.7/site-packages/flask/views.py", line 88, in view
    return self.dispatch_request(*args, **kwargs)
  File "/Users/iman/Python/rest_training/lib/python3.7/site-packages/flask_restful/__init__.py", line 573, in dispatch_request
    resp = meth(*args, **kwargs)
  File "part-1.3-log_and_error/app.py", line 54, in get
    raise Exception('Test internal server error')
Exception: Test internal server error
[2019-01-13 08:52:58,910] {part-1.3-log_and_error/app.py:27} WARNING - REQUEST_LOG	{"request": null, "response": {"message": "Internal Server Error"}}
[2019-01-13 08:53:02,418] {/Users/iman/Python/rest_training/lib/python3.7/site-packages/flask/app.py:1761} ERROR - Exception on /name [GET]
Traceback (most recent call last):
  File "/Users/iman/Python/rest_training/lib/python3.7/site-packages/flask/app.py", line 1813, in full_dispatch_request
    rv = self.dispatch_request()
  File "/Users/iman/Python/rest_training/lib/python3.7/site-packages/flask/app.py", line 1799, in dispatch_request
    return self.view_functions[rule.endpoint](**req.view_args)
  File "/Users/iman/Python/rest_training/lib/python3.7/site-packages/flask_restful/__init__.py", line 458, in wrapper
    resp = resource(*args, **kwargs)
  File "/Users/iman/Python/rest_training/lib/python3.7/site-packages/flask/views.py", line 88, in view
    return self.dispatch_request(*args, **kwargs)
  File "/Users/iman/Python/rest_training/lib/python3.7/site-packages/flask_restful/__init__.py", line 573, in dispatch_request
    resp = meth(*args, **kwargs)
  File "part-1.3-log_and_error/app.py", line 54, in get
    raise Exception('Test internal server error')
Exception: Test internal server error
[2019-01-13 08:53:02,420] {part-1.3-log_and_error/app.py:27} WARNING - REQUEST_LOG	{"request": null, "response": {"message": "Internal Server Error"}}
[2019-01-13 08:53:20,415] {/Users/iman/Python/rest_training/lib/python3.7/site-packages/flask/app.py:1761} ERROR - Exception on /name [GET]
Traceback (most recent call last):
  File "/Users/iman/Python/rest_training/lib/python3.7/site-packages/flask/app.py", line 1813, in full_dispatch_request
    rv = self.dispatch_request()
  File "/Users/iman/Python/rest_training/lib/python3.7/site-packages/flask/app.py", line 1799, in dispatch_request
    return self.view_functions[rule.endpoint](**req.view_args)
  File "/Users/iman/Python/rest_training/lib/python3.7/site-packages/flask_restful/__init__.py", line 458, in wrapper
    resp = resource(*args, **kwargs)
  File "/Users/iman/Python/rest_training/lib/python3.7/site-packages/flask/views.py", line 88, in view
    return self.dispatch_request(*args, **kwargs)
  File "/Users/iman/Python/rest_training/lib/python3.7/site-packages/flask_restful/__init__.py", line 573, in dispatch_request
    resp = meth(*args, **kwargs)
  File "part-1.3-log_and_error/app.py", line 54, in get
    raise Exception('Test internal server error')
Exception: Test internal server error
[2019-01-13 08:53:20,418] {part-1.3-log_and_error/app.py:27} WARNING - REQUEST_LOG	{"request": null, "response": {"message": "Internal Server Error"}}
[2019-01-13 08:54:03,515] {/Users/iman/Python/rest_training/lib/python3.7/site-packages/flask/app.py:1761} ERROR - Exception on /name [GET]
Traceback (most recent call last):
  File "/Users/iman/Python/rest_training/lib/python3.7/site-packages/flask/app.py", line 1813, in full_dispatch_request
    rv = self.dispatch_request()
  File "/Users/iman/Python/rest_training/lib/python3.7/site-packages/flask/app.py", line 1799, in dispatch_request
    return self.view_functions[rule.endpoint](**req.view_args)
  File "/Users/iman/Python/rest_training/lib/python3.7/site-packages/flask_restful/__init__.py", line 458, in wrapper
    resp = resource(*args, **kwargs)
  File "/Users/iman/Python/rest_training/lib/python3.7/site-packages/flask/views.py", line 88, in view
    return self.dispatch_request(*args, **kwargs)
  File "/Users/iman/Python/rest_training/lib/python3.7/site-packages/flask_restful/__init__.py", line 573, in dispatch_request
    resp = meth(*args, **kwargs)
  File "part-1.3-log_and_error/app.py", line 54, in get
    raise Exception('Enginner juga manusia')
Exception: Test internal server error
[2019-01-13 08:54:03,518] {part-1.3-log_and_error/app.py:27} WARNING - REQUEST_LOG	{"request": null, "response": {"message": "Internal Server Error"}}
[2019-01-13 08:54:12,535] {/Users/iman/Python/rest_training/lib/python3.7/site-packages/flask/app.py:1761} ERROR - Exception on /name [GET]
Traceback (most recent call last):
  File "/Users/iman/Python/rest_training/lib/python3.7/site-packages/flask/app.py", line 1813, in full_dispatch_request
    rv = self.dispatch_request()
  File "/Users/iman/Python/rest_training/lib/python3.7/site-packages/flask/app.py", line 1799, in dispatch_request
    return self.view_functions[rule.endpoint](**req.view_args)
  File "/Users/iman/Python/rest_training/lib/python3.7/site-packages/flask_restful/__init__.py", line 458, in wrapper
    resp = resource(*args, **kwargs)
  File "/Users/iman/Python/rest_training/lib/python3.7/site-packages/flask/views.py", line 88, in view
    return self.dispatch_request(*args, **kwargs)
  File "/Users/iman/Python/rest_training/lib/python3.7/site-packages/flask_restful/__init__.py", line 573, in dispatch_request
    resp = meth(*args, **kwargs)
  File "part-1.3-log_and_error/app.py", line 54, in get
    raise Exception('Enginner juga manusia')
Exception: Test internal server error
[2019-01-13 08:54:12,537] {part-1.3-log_and_error/app.py:27} WARNING - REQUEST_LOG	{"request": null, "response": {"message": "Internal Server Error"}}
[2019-01-13 08:54:19,462] {/Users/iman/Python/rest_training/lib/python3.7/site-packages/flask/app.py:1761} ERROR - Exception on /name [GET]
Traceback (most recent call last):
  File "/Users/iman/Python/rest_training/lib/python3.7/site-packages/flask/app.py", line 1813, in full_dispatch_request
    rv = self.dispatch_request()
  File "/Users/iman/Python/rest_training/lib/python3.7/site-packages/flask/app.py", line 1799, in dispatch_request
    return self.view_functions[rule.endpoint](**req.view_args)
  File "/Users/iman/Python/rest_training/lib/python3.7/site-packages/flask_restful/__init__.py", line 458, in wrapper
    resp = resource(*args, **kwargs)
  File "/Users/iman/Python/rest_training/lib/python3.7/site-packages/flask/views.py", line 88, in view
    return self.dispatch_request(*args, **kwargs)
  File "/Users/iman/Python/rest_training/lib/python3.7/site-packages/flask_restful/__init__.py", line 573, in dispatch_request
    resp = meth(*args, **kwargs)
  File "part-1.3-log_and_error/app.py", line 54, in get
    raise Exception('Enginner juga manusia')
Exception: Enginner juga manusia
[2019-01-13 08:54:19,466] {part-1.3-log_and_error/app.py:27} WARNING - REQUEST_LOG	{"request": null, "response": {"message": "Internal Server Error"}}
[2019-01-13 08:55:04,126] {part-1.3-log_and_error/app.py:27} WARNING - REQUEST_LOG	{"request": null, "response": {"message": "The requested URL was not found on the server.  If you entered the URL manually please check your spelling and try again."}}
[2019-01-13 08:55:21,741] {part-1.3-log_and_error/app.py:27} WARNING - REQUEST_LOG	{"request": null, "response": {"message": "The requested URL was not found on the server.  If you entered the URL manually please check your spelling and try again."}}
[2019-01-13 08:55:58,862] {part-1.3-log_and_error/app.py:27} WARNING - REQUEST_LOG	{"request": null, "response": {"message": "The requested URL was not found on the server.  If you entered the URL manually please check your spelling and try again."}}
[2019-01-13 08:56:02,454] {/Users/iman/Python/rest_training/lib/python3.7/site-packages/flask/app.py:1761} ERROR - Exception on /name [GET]
Traceback (most recent call last):
  File "/Users/iman/Python/rest_training/lib/python3.7/site-packages/flask/app.py", line 1813, in full_dispatch_request
    rv = self.dispatch_request()
  File "/Users/iman/Python/rest_training/lib/python3.7/site-packages/flask/app.py", line 1799, in dispatch_request
    return self.view_functions[rule.endpoint](**req.view_args)
  File "/Users/iman/Python/rest_training/lib/python3.7/site-packages/flask_restful/__init__.py", line 458, in wrapper
    resp = resource(*args, **kwargs)
  File "/Users/iman/Python/rest_training/lib/python3.7/site-packages/flask/views.py", line 88, in view
    return self.dispatch_request(*args, **kwargs)
  File "/Users/iman/Python/rest_training/lib/python3.7/site-packages/flask_restful/__init__.py", line 573, in dispatch_request
    resp = meth(*args, **kwargs)
  File "part-1.3-log_and_error/app.py", line 54, in get
    raise Exception()
Exception: Enginner juga manusia
[2019-01-13 08:56:02,457] {part-1.3-log_and_error/app.py:27} WARNING - REQUEST_LOG	{"request": null, "response": {"message": "Internal Server Error"}}
[2019-01-13 08:56:48,235] {part-1.3-log_and_error/app.py:27} WARNING - REQUEST_LOG	{"request": null, "response": {"message": "ooops maaf, engineer juga manusia"}}
[2019-01-13 09:01:22,750] {part-1.3-log_and_error/app.py:23} WARNING - REQUEST_LOG	{"request": null, "response": {"message": "The requested URL was not found on the server.  If you entered the URL manually please check your spelling and try again."}}
